Workbook

Sheet Instrucciones
B2: Cuestionario del Modelo de Negocio Canvas — Proyecto de desarrollo de software
B3: Instituto Tecnológico de Morelia · TecNM · Ingeniería de Software
B5: Para qué sirve | C5: Este libro acompaña a la presentación «Modelo de Negocio Canvas». Contiene las 45 preguntas guía de los nueve bloques, con celdas para que tu equipo capture las respuestas. Al llenarlo se arma automáticamente el lienzo y se calcula tu avance.
B7: Cómo se llena | C7: Escribe únicamente en las celdas de fondo amarillo. El resto de las celdas contiene fórmulas o texto de referencia y no debe modificarse.
B9: Orden sugerido | C9: Contesta los bloques en el orden en que aparecen (1 Segmentos, 2 Propuesta de valor, 3 Canales, 4 Relación, 5 Ingresos, 6 Recursos, 7 Actividades, 8 Socios, 9 Costos). Ese es el orden en que se construye un modelo de negocio.
B11: Extensión esperada | C11: Entre 40 y 400 caracteres por respuesta. La columna «Estado» marca «Pendiente» si está vacía y «Muy breve» si tiene menos de 40 caracteres.
B13: Hoja «Lienzo» | C13: Se llena sola con tus respuestas y reproduce el lienzo de una sola página. Úsala para revisar la coherencia del conjunto y para vaciar el contenido en la plantilla de la presentación.
B15: Hoja «Monetización» | C15: Calculadora de ingresos, costos, punto de equilibrio y relación LTV/CAC. Cambia solo los supuestos en amarillo y observa cómo se mueven los resultados.
B17: Hoja «Checklist» | C17: Prueba de coherencia del modelo. Elige Sí, Parcial o No en cada criterio; el semáforo indica si la propuesta está lista para presentarse.
B19: Entregable | C19: Este archivo con el cuestionario contestado y el checklist en verde, más la presentación con las diapositivas de plantilla completas.
B22: LEYENDA
C23: Celda de captura: escribe aquí.
C24: Celda de referencia o texto fijo: no la modifiques.
C25: Celda calculada con fórmula: no la modifiques.
B27: Equipo: | C27: Rafael Piedra Sanchez
B28: Nombre del proyecto: | C28: Ally-Educ

Sheet Cuestionario
B2: Cuestionario guía — los nueve bloques del Business Model Canvas
B3: Escribe solo en la columna «Respuesta del equipo» (celdas amarillas). Entre 40 y 400 caracteres por respuesta.
B5: Bloque | C5: # | D5: Pregunta guía | E5: Respuesta del equipo | F5: Qué debe contener una buena respuesta | G5: Estado
B6: BLOQUE 1 — SEGMENTOS DE CLIENTES · ¿Para quién creamos valor?
B7: Segmentos de clientes | C7: 1.1 | D7: ¿Para quién creamos valor, en una frase? | E7: Para escuelas rurales con equipos inutilizados, estudiantes, habitantes sin internet y autoridades educativas que buscan cerrar la brecha digital. | F7: Un grupo concreto y acotado: sector, tamaño y ubicación. La palabra «todos» invalida la respuesta. | G7: =IF(LEN(E7)=0,"Pendiente",IF(LEN(E7)<40,"Muy breve","Completa")) -> Completa
B8: Segmentos de clientes | C8: 1.2 | D8: ¿Quién usa el software a diario y quién firma el pago? | E8: Lo usa diariamente los alumnos y publico general. El que paga; es la escuela (Asociacion de padres), la counidad y ayuntamientos | F8: Los dos papeles nombrados por separado, con su puesto dentro de la organización. | G8: =IF(LEN(E8)=0,"Pendiente",IF(LEN(E8)<40,"Muy breve","Completa")) -> Completa
B9: Segmentos de clientes | C9: 1.3 | D9: ¿Qué segmento sufre el problema con más intensidad y frecuencia? | E9: Las escuelas rurales que tienen dispositivos donados o ya cuentan con ellos (tablets/PCs) pero que estan arrubados formando un basurero tecnologico por falta de red | F9: Un segmento elegido y la razón por la que el problema duele más ahí que en otros. | G9: =IF(LEN(E9)=0,"Pendiente",IF(LEN(E9)<40,"Muy breve","Completa")) -> Completa
B10: Segmentos de clientes | C10: 1.4 | D10: ¿Cuántos son, dónde están y cómo los contactamos? | E10: Miles de escuelas rurales de distintos niveles. Donde el contacto es presencial con directores, comites de padres de familia y autoridades ejidales. | F10: Un número estimado con su fuente y al menos una vía concreta de contacto. | G10: =IF(LEN(E10)=0,"Pendiente",IF(LEN(E10)<40,"Muy breve","Completa")) -> Completa
B11: Segmentos de clientes | C11: 1.5 | D11: ¿Con qué segmento arrancamos y cuál dejamos para después? | E11: Arrancamos con escuelas publicas rurales con un aula especializada (sala de informatica), para despues escalar la señal al resto de la comunidad | F11: Un segmento de entrada y el criterio por el que fue elegido. | G11: =IF(LEN(E11)=0,"Pendiente",IF(LEN(E11)<40,"Muy breve","Completa")) -> Completa
B13: BLOQUE 2 — PROPUESTA DE VALOR · ¿Qué ofrecemos y por qué nos eligen?
B14: Propuesta de valor | C14: 2.1 | D14: ¿Qué problema específico resolvemos y para quién? | E14: Ponemos en uso los equipos inactivos de la escuela creando un aula interactiva y damos acceso a informacion a la comunidad sin depender de internet. | F14: Un problema observable en el trabajo del cliente, no la ausencia de un software. | G14: =IF(LEN(E14)=0,"Pendiente",IF(LEN(E14)<40,"Muy breve","Completa")) -> Completa
B15: Propuesta de valor | C15: 2.2 | D15: ¿Qué hace hoy el cliente sin nosotros y qué le cuesta? | E15: La escuela tiene equipo tecnologico que no usa. Los estudiantes gastan su saldo celular (si hay red) para investigar, limitando su aprendizaje y generando un gasto familiar | F15: La alternativa actual nombrada (papel, hoja de cálculo, otro sistema) y su costo en tiempo o dinero. | G15: =IF(LEN(E15)=0,"Pendiente",IF(LEN(E15)<40,"Muy breve","Completa")) -> Completa
B16: Propuesta de valor | C16: 2.3 | D16: ¿Qué gana de forma medible: tiempo, dinero, errores evitados, cumplimiento? | E16: La escuela recupera su inversion en hardware y los alumnos acceden a terabytes de conocimiento y un Tutor IA ahorrando 100% de datos moviles. | F16: Al menos una cifra o una comparación de antes y después. | G16: =IF(LEN(E16)=0,"Pendiente",IF(LEN(E16)<40,"Muy breve","Completa")) -> Completa
B17: Propuesta de valor | C17: 2.4 | D17: ¿Por qué nosotros y no la alternativa que ya tiene? | E17: Porque no cobramos una costotsa renta mensual de internet satelita (o por fibra), si no que instalamos una intranet local sustentable que opera de forma autonoma. | F17: Un diferenciador que la alternativa actual no puede ofrecer. | G17: =IF(LEN(E17)=0,"Pendiente",IF(LEN(E17)<40,"Muy breve","Completa")) -> Completa
B18: Propuesta de valor | C18: 2.5 | D18: ¿Qué queda fuera del alcance de la primera versión? | E18: Queda fuera del alcance dar acceso a internet, ya que el sistema funcionará únicamente como una red privada y al conectarte, solo te permitirá consultar documentos, archivos y la IA que ya estan dentro del propio servidor local. | F18: Una lista corta de exclusiones explícitas. | G18: =IF(LEN(E18)=0,"Pendiente",IF(LEN(E18)<40,"Muy breve","Completa")) -> Completa
B20: BLOQUE 3 — CANALES · ¿Cómo llegamos al cliente?
B21: Canales | C21: 3.1 | D21: ¿Cómo se entera el cliente de que existimos? | E21: Mediante visitas presenciales a escuelas, reuniones con directores, asambleas ejidales y alianzas con CONAFE | F21: Uno o dos canales concretos. «Redes sociales» sin más detalle no cuenta. | G21: =IF(LEN(E21)=0,"Pendiente",IF(LEN(E21)<40,"Muy breve","Completa")) -> Completa
B22: Canales | C22: 3.2 | D22: ¿Cómo puede probar el producto antes de pagar? | E22: Llevando un microservidor portatil a la escuela para hacer una demostracion en vivo de como la IA y los siuladores funcionan en sus propios dispositivos sin ninguna conexión. | F22: Un mecanismo de prueba definido, con su duración o su alcance. | G22: =IF(LEN(E22)=0,"Pendiente",IF(LEN(E22)<40,"Muy breve","Completa")) -> Completa
B23: Canales | C23: 3.3 | D23: ¿Cómo lo contrata, lo instala y lo empieza a usar? | E23: Primero la escuela aprueba el proyecto, instalamos el servidor para la aula especializada y las antenas exterioes. Y ahora los usuarios se pueden conectar al WIFI | F23: El recorrido de alta descrito en pasos, desde la decisión hasta el primer uso real. | G23: =IF(LEN(E23)=0,"Pendiente",IF(LEN(E23)<40,"Muy breve","Completa")) -> Completa
B24: Canales | C24: 3.4 | D24: ¿Por dónde recibe soporte, capacitación y actualizaciones? | E24: Reciben una capacitacion presencial a docentes para usar el aula (y el portal). Ademas, de actualizaciones y soporte fisico mediante visitas tecnicas programadas | F24: Canal de soporte, horario de atención y forma de entrega de las actualizaciones. | G24: =IF(LEN(E24)=0,"Pendiente",IF(LEN(E24)<40,"Muy breve","Completa")) -> Completa
B25: Canales | C25: 3.5 | D25: ¿Qué canal es el más barato por cliente adquirido? | E25: La alianza con autoridades municipales o CONAFE, ya que un solo acuerdo puede darnos multiples escuelas de la region | F25: Una comparación, aunque sea estimada, con el supuesto en que se apoya. | G25: =IF(LEN(E25)=0,"Pendiente",IF(LEN(E25)<40,"Muy breve","Completa")) -> Completa
B27: BLOQUE 4 — RELACIÓN CON CLIENTES · ¿Cómo conservamos al cliente?
B28: Relación con clientes | C28: 4.1 | D28: ¿Qué tipo de relación espera cada segmento y cuál está dispuesto a pagar? | E28: La escuela espera capacitacion humana y soporte tecnico. Y la comunidad espera que el servicio de compra de fichas presenciales sea rapido y confiable. | F28: El tipo nombrado: autoservicio, asistencia personal, comunidad o éxito del cliente. | G28: =IF(LEN(E28)=0,"Pendiente",IF(LEN(E28)<40,"Muy breve","Completa")) -> Completa
B29: Relación con clientes | C29: 4.2 | D29: ¿Cómo acompañamos al cliente en sus primeros días de uso? | E29: Con uno de nuestros compañeros (integrantes) del proyecto se quede en el sitio para poder configruar las tabletas/PC del aula especializada y enseñar a los docentes a usar el Tutor IA y los simuladores, ademas de crear una guia de uso para las fichas y acceso al portal. | F29: Acciones concretas de puesta en marcha, con tiempos. | G29: =IF(LEN(E29)=0,"Pendiente",IF(LEN(E29)<40,"Muy breve","Completa")) -> Completa
B30: Relación con clientes | C30: 4.3 | D30: ¿Qué hacemos para que no nos abandone y cómo lo detectamos a tiempo? | E30: Ofrecemos polizas de actualizacion de contenido (nuevos libros, mejores IA's) para que la escual vea valor mantener el sistema vigente año tras año | F30: Una señal medible de riesgo de abandono y la acción que se dispara con ella. | G30: =IF(LEN(E30)=0,"Pendiente",IF(LEN(E30)<40,"Muy breve","Completa")) -> Completa
B31: Relación con clientes | C31: 4.4 | D31: ¿Qué parte de la relación se automatiza y cuál es humana? | E31: El portal cautivo automatiza el acceso tras ingresar el codigo PIN. La venta de las fichas, la instalacion y el mantenimiento son estrictamente humanos. | F31: La frontera entre ambas, declarada de forma explícita. | G31: =IF(LEN(E31)=0,"Pendiente",IF(LEN(E31)<40,"Muy breve","Completa")) -> Completa
B32: Relación con clientes | C32: 4.5 | D32: ¿Cuánto cuesta al mes sostener esa relación por cliente? | E32: EL mayor costo son los viaticos de transporte a la comunidad para entregar los lotes de fichas fisicas, cobrar y realizar el mantenimeinto. | F32: Una estimación en pesos o en horas de trabajo por cliente. | G32: =IF(LEN(E32)=0,"Pendiente",IF(LEN(E32)<40,"Muy breve","Completa")) -> Completa
B34: BLOQUE 5 — FUENTES DE INGRESOS · ¿Cómo entra el dinero?
B35: Fuentes de ingresos | C35: 5.1 | D35: ¿Por qué valor concreto está dispuesto a pagar el cliente? | E35: La escuela paga por revivir su aula tecnologica y el mantenimiento. La comunidad paga por acceder a gerraientas de estudio sin gastar en saldo celular. | F35: El valor recibido, no la funcionalidad entregada. | G35: =IF(LEN(E35)=0,"Pendiente",IF(LEN(E35)<40,"Muy breve","Completa")) -> Completa
B36: Fuentes de ingresos | C36: 5.2 | D36: ¿Cuánto gasta hoy en resolver ese problema por otros medios? | E36: Las escuelas no pueden pagar internet satelital permanente y con buena velocidad (para muchos usuarios), y los padres gastan constantemente en recargas de saldo para tareas escolares. | F36: Una cifra con su origen: entrevista, cotización o estimación documentada. | G36: =IF(LEN(E36)=0,"Pendiente",IF(LEN(E36)<40,"Muy breve","Completa")) -> Completa
B37: Fuentes de ingresos | C37: 5.3 | D37: ¿Cómo cobramos: mensual, anual, por uso, único, por comisión? | E37: 1. La venta presencial de fichas/pines de acceso (tiempo de duracion de cada pin es semanalment o mensualmente) 2. Polizas de mantenimiento y actualizacion a la escuela 3. Venta inicial de infraestructura | F37: El modelo elegido y la unidad de cobro (por usuario, por sucursal, por transacción). | G37: =IF(LEN(E37)=0,"Pendiente",IF(LEN(E37)<40,"Muy breve","Completa")) -> Completa
B38: Fuentes de ingresos | C38: 5.4 | D38: ¿Cuál es el precio, cómo lo justificamos y qué planes ofrecemos? | E38: Fichas muy economicas (ej. Semanales, mensuales) pagadas en efectivo en la cooperativa o algun otro sitio. Y Polizas anuales a la escuela para actualizaciones y mantenimiento | F38: Precio justificado en el valor entregado y al menos dos planes diferenciados. | G38: =IF(LEN(E38)=0,"Pendiente",IF(LEN(E38)<40,"Muy breve","Completa")) -> Completa
B39: Fuentes de ingresos | C39: 5.5 | D39: ¿Qué porcentaje del ingreso total aporta cada fuente? | E39: La venta de infraestructura (Aula + antenas) aporta la capital inicial. Y las polizas a esculas y venta de fichas en efectivo dan ingresos mensuales. | F39: Una distribución cuyos porcentajes sumen cien. | G39: =IF(LEN(E39)=0,"Pendiente",IF(LEN(E39)<40,"Muy breve","Completa")) -> Completa
B41: BLOQUE 6 — RECURSOS CLAVE · ¿Qué necesitamos para operar?
B42: Recursos clave | C42: 6.1 | D42: ¿Qué perfiles técnicos necesita el equipo y con qué dedicación? | E42: Ingenieros capaces de desplegar contenedores docker, configurar Open WebUI/RAG y tecnicos para la instalacion fisica de redes y antenas 5GHz. | F42: Perfiles, cantidad y dedicación: tiempo completo o parcial. | G42: =IF(LEN(E42)=0,"Pendiente",IF(LEN(E42)<40,"Muy breve","Completa")) -> Completa
B43: Recursos clave | C43: 6.2 | D43: ¿Qué infraestructura requiere el sistema y cuánto cuesta al mes? | E43: Requiere un microservidor central, Antenas de largo alcance 5GHz y los dispositivos con los que ya cuenta la escuela. El costo de nube es cero al ser una infraestructura 100% offline | F43: Servicios nombrados y un costo mensual estimado. | G43: =IF(LEN(E43)=0,"Pendiente",IF(LEN(E43)<40,"Muy breve","Completa")) -> Completa
B44: Recursos clave | C44: 6.3 | D44: ¿Qué datos necesitamos, cómo los obtenemos y cómo los protegemos? | E44: Archivos Publicos masivos (Wikipedia, PhET, Libros) ingresados mediante Discos Duros locales al servidor. Ademas, no capturaremos datos sensibles de usuarios (alumnos, profesores, usuarios en general) | F44: Origen de los datos y la medida de protección o la base legal de su tratamiento. | G44: =IF(LEN(E44)=0,"Pendiente",IF(LEN(E44)<40,"Muy breve","Completa")) -> Completa
B45: Recursos clave | C45: 6.4 | D45: ¿Qué activo es difícil de copiar por un competidor? | E45: La integracion en Docker con Inteligencia Artificial que no alucine y logistica de distribucion en la comunidad. | F45: Un activo concreto y la razón por la que no es fácil de replicar. | G45: =IF(LEN(E45)=0,"Pendiente",IF(LEN(E45)<40,"Muy breve","Completa")) -> Completa
B46: Recursos clave | C46: 6.5 | D46: ¿De qué licencias o servicios de terceros dependemos de forma crítica? | E46: Usamos tecnologias de codigo abierto (Docker, Ollama, Modelos LLM locales), eliminando el pago de licencias a terceros | F46: Servicios nombrados y el efecto que tendría perderlos. | G46: =IF(LEN(E46)=0,"Pendiente",IF(LEN(E46)<40,"Muy breve","Completa")) -> Completa
B48: BLOQUE 7 — ACTIVIDADES CLAVE · ¿Qué hacemos de forma sostenida?
...

Sheet Lienzo
B2: Lienzo del modelo de negocio — se arma solo con tus respuestas
B3: Esta hoja no se edita: reúne las respuestas capturadas en la hoja «Cuestionario». Si algo se ve vacío, esa pregunta sigue pendiente.
B5: 8. Socios clave | C5: 7. Actividades clave | D5: 2. Propuesta de valor | E5: 4. Relación con clientes | F5: 1. Segmentos de clientes
B6: =IF(COUNTA(Cuestionario!E56:E60)=0,"","• "&_xlfn.TEXTJOIN(CHAR(10)&"• ",TRUE(),Cuestionario!E56:E60)) -> • Los proveedoees de hardware (servidores y antenas 5GHz) asi como los creados de los modelos base de inteligencia artificial (LLMs) • El Hardware de telecomunicaciones: donde un aumento de precio haria que se viera reflejado en el costo de instalacion (y/o contratacion inicial) que se cobra a la escuela o el ayuntamiento • La CONAFE nos conectaria con comunidades rurales de una manera mas sencilla. Y tiendas locales de la comunidad (sitio oficial, abarrotes, cooperativas escolares...) quienes actuaran como nuestros distribuidores de los pines de acceso • Las escuelas, las cuales resguardan fisicamente nuestro servidor dentro de sus instalaciones, asi como los ejidos que autorizan el uso de los espacios. • Nosotros damos la tecnologia. La escuela pone las tabletas/PC y la seguridad fisica. EL punto de venta local gana una comision por vender los pines de acceso | C6: =IF(COUNTA(Cuestionario!E49:E53)=0,"","• "&_xlfn.TEXTJOIN(CHAR(10)&"• ",TRUE(),Cuestionario!E49:E53)) -> • Generar e imprimir los lotes de codigos PIN y gestionar la logistica presencial para entregarlos al punto de venta de la comunidad • El despliegue fisico del microservidor en el aula especializada y las actualizaciones a la infraestructura (RAG de informacion e IA) para que el sistema sea optimo • Interno: Configuracion de software, IA y sistema logistico de pines de acceso. Externo: compra de hardware y si es necesario (aunque posiblemente no) la contratacion de mano de obra local para el cableado. • Aislando el trafico de usuarios (una para el aula y otra para el prueblo) y visitando presencialmente la escuela ante fallas de hardware. • Despliegue basado en contenedores Docker, lo que nos permite el manejo aislado del sistema completo, y podemos hacer actualizaciones e implementaciones rapidas via USB en las visitas tecnicas. | D6: =IF(COUNTA(Cuestionario!E14:E18)=0,"","• "&_xlfn.TEXTJOIN(CHAR(10)&"• ",TRUE(),Cuestionario!E14:E18)) -> • Ponemos en uso los equipos inactivos de la escuela creando un aula interactiva y damos acceso a informacion a la comunidad sin depender de internet. • La escuela tiene equipo tecnologico que no usa. Los estudiantes gastan su saldo celular (si hay red) para investigar, limitando su aprendizaje y generando un gasto familiar • La escuela recupera su inversion en hardware y los alumnos acceden a terabytes de conocimiento y un Tutor IA ahorrando 100% de datos moviles. • Porque no cobramos una costotsa renta mensual de internet satelita (o por fibra), si no que instalamos una intranet local sustentable que opera de forma autonoma. • Queda fuera del alcance dar acceso a internet, ya que el sistema funcionará únicamente como una red privada y al conectarte, solo te permitirá consultar documentos, archivos y la IA que ya estan dentro del propio servidor local. | E6: =IF(COUNTA(Cuestionario!E28:E32)=0,"","• "&_xlfn.TEXTJOIN(CHAR(10)&"• ",TRUE(),Cuestionario!E28:E32)) -> • La escuela espera capacitacion humana y soporte tecnico. Y la comunidad espera que el servicio de compra de fichas presenciales sea rapido y confiable. • Con uno de nuestros compañeros (integrantes) del proyecto se quede en el sitio para poder configruar las tabletas/PC del aula especializada y enseñar a los docentes a usar el Tutor IA y los simuladores, ademas de crear una guia de uso para las fichas y acceso al portal. • Ofrecemos polizas de actualizacion de contenido (nuevos libros, mejores IA's) para que la escual vea valor mantener el sistema vigente año tras año • El portal cautivo automatiza el acceso tras ingresar el codigo PIN. La venta de las fichas, la instalacion y el mantenimiento son estrictamente humanos. • EL mayor costo son los viaticos de transporte a la comunidad para entregar los lotes de fichas fisicas, cobrar y realizar el mantenimeinto. | F6: =IF(COUNTA(Cuestionario!E7:E11)=0,"","• "&_xlfn.TEXTJOIN(CHAR(10)&"• ",TRUE(),Cuestionario!E7:E11)) -> • Para escuelas rurales con equipos inutilizados, estudiantes, habitantes sin internet y autoridades educativas que buscan cerrar la brecha digital. • Lo usa diariamente los alumnos y publico general. El que paga; es la escuela (Asociacion de padres), la counidad y ayuntamientos • Las escuelas rurales que tienen dispositivos donados o ya cuentan con ellos (tablets/PCs) pero que estan arrubados formando un basurero tecnologico por falta de red • Miles de escuelas rurales de distintos niveles. Donde el contacto es presencial con directores, comites de padres de familia y autoridades ejidales. • Arrancamos con escuelas publicas rurales con un aula especializada (sala de informatica), para despues escalar la señal al resto de la comunidad
C10: 6. Recursos clave | E10: 3. Canales
C11: =IF(COUNTA(Cuestionario!E42:E46)=0,"","• "&_xlfn.TEXTJOIN(CHAR(10)&"• ",TRUE(),Cuestionario!E42:E46)) -> • Ingenieros capaces de desplegar contenedores docker, configurar Open WebUI/RAG y tecnicos para la instalacion fisica de redes y antenas 5GHz. • Requiere un microservidor central, Antenas de largo alcance 5GHz y los dispositivos con los que ya cuenta la escuela. El costo de nube es cero al ser una infraestructura 100% offline • Archivos Publicos masivos (Wikipedia, PhET, Libros) ingresados mediante Discos Duros locales al servidor. Ademas, no capturaremos datos sensibles de usuarios (alumnos, profesores, usuarios en general) • La integracion en Docker con Inteligencia Artificial que no alucine y logistica de distribucion en la comunidad. • Usamos tecnologias de codigo abierto (Docker, Ollama, Modelos LLM locales), eliminando el pago de licencias a terceros | E11: =IF(COUNTA(Cuestionario!E21:E25)=0,"","• "&_xlfn.TEXTJOIN(CHAR(10)&"• ",TRUE(),Cuestionario!E21:E25)) -> • Mediante visitas presenciales a escuelas, reuniones con directores, asambleas ejidales y alianzas con CONAFE • Llevando un microservidor portatil a la escuela para hacer una demostracion en vivo de como la IA y los siuladores funcionan en sus propios dispositivos sin ninguna conexión. • Primero la escuela aprueba el proyecto, instalamos el servidor para la aula especializada y las antenas exterioes. Y ahora los usuarios se pueden conectar al WIFI • Reciben una capacitacion presencial a docentes para usar el aula (y el portal). Ademas, de actualizaciones y soporte fisico mediante visitas tecnicas programadas • La alianza con autoridades municipales o CONAFE, ya que un solo acuerdo puede darnos multiples escuelas de la region
B14: 9. Estructura de costos | D14: 5. Fuentes de ingresos
B15: =IF(COUNTA(Cuestionario!E63:E67)=0,"","• "&_xlfn.TEXTJOIN(CHAR(10)&"• ",TRUE(),Cuestionario!E63:E67)) -> • 1. Hardware (Servidor y antenas). 2. Viaticos (Visitas de mantenimiento y cobro). 3. Generacion e Impresión de fichas. 4. Horas de Desarrollo 5. Mano de obra de red • Ampliar la cobertura requiere compras mas antenas exteriores. Aumentar el contenido requiere discos duros de mayor capacidad para el servidor • Al principio, adquirir una escuela requiere viajes de venta especial. Y despues, antenderla cuesta viaticos mensuales del equipo que recolecta el efectivo y hace mantenimiento • Por valor. Ya que rescatamos el hardware abandonado y llevamos educacion e IA a un prueblo sin internet, justificando la inversion en la infraestructura. • Cobrando la infraestructura y el aula especializada a la escuela/municipio, asi como cubriendo la operación logistica. El punto de equilibrio se alcanzaria relativamente rapido | D15: =IF(COUNTA(Cuestionario!E35:E39)=0,"","• "&_xlfn.TEXTJOIN(CHAR(10)&"• ",TRUE(),Cuestionario!E35:E39)) -> • La escuela paga por revivir su aula tecnologica y el mantenimiento. La comunidad paga por acceder a gerraientas de estudio sin gastar en saldo celular. • Las escuelas no pueden pagar internet satelital permanente y con buena velocidad (para muchos usuarios), y los padres gastan constantemente en recargas de saldo para tareas escolares. • 1. La venta presencial de fichas/pines de acceso (tiempo de duracion de cada pin es semanalment o mensualmente) 2. Polizas de mantenimiento y actualizacion a la escuela 3. Venta inicial de infraestructura • Fichas muy economicas (ej. Semanales, mensuales) pagadas en efectivo en la cooperativa o algun otro sitio. Y Polizas anuales a la escuela para actualizaciones y mantenimiento • La venta de infraestructura (Aula + antenas) aporta la capital inicial. Y las polizas a esculas y venta de fichas en efectivo dan ingresos mensuales.
B20: Revisión de coherencia: cada segmento debe tener un canal, cada propuesta de valor una fuente de ingresos, y cada costo debe nacer de un recurso, una actividad o un socio declarado.

Sheet Monetización
B2: Calculadora del modelo de ingresos y punto de equilibrio
B3: Cambia únicamente las celdas amarillas. Los resultados se recalculan solos. Todas las cifras son estimaciones del equipo y deben poder explicarse.
B5: SUPUESTOS DEL MODELO — escribe aquí
B6: Precio de la suscripción por cliente al mes | C6: 899 | D6: Precio de lista del plan principal.
B7: Ingreso único por implementación (por cliente) | C7: 2500 | D7: Cobro de una sola vez al dar de alta al cliente. Escribe 0 si no aplica.
B8: Clientes activos al cierre del primer año | C8: 110 | D8: Meta realista, no aspiracional. Compárala con el punto de equilibrio calculado abajo.
B9: Clientes nuevos por mes (promedio del año) | C9: 9 | D9: Ritmo de venta que el equipo puede sostener.
B10: Costo variable por cliente al mes (nube, mensajería, soporte) | C10: 95 | D10: Lo que cuesta atender a un cliente más.
B11: Comisión de la pasarela de pago | C11: 0.03 | D11: Se aplica sobre el ingreso cobrado.
B12: Costos fijos mensuales (nómina, infraestructura base, licencias) | C12: 78000 | D12: No dependen del número de clientes.
B13: Costo de adquirir un cliente (CAC) | C13: 1800 | D13: Gasto de venta y mercadotecnia dividido entre los clientes conseguidos.
B14: Permanencia promedio del cliente (meses) | C14: 18 | D14: Si el abandono mensual fuera del 5%, la permanencia sería de 20 meses.
B16: RESULTADOS MENSUALES
B17: Ingreso recurrente mensual (MRR) | C17: =C6*C8 -> 98890 | D17: Precio mensual multiplicado por los clientes activos.
B18: Ingreso por implementaciones del mes | C18: =C7*C9 -> 22500 | D18: Ingreso no recurrente: depende de cuántos clientes nuevos entran.
B19: Ingreso total del mes | C19: =C17+C18 -> 121390 | D19: Suma de lo recurrente y lo no recurrente.
B20: Costos variables del mes | C20: =C10*C8+C19*C11 -> 14091.7 | D20: Costo por cliente más la comisión de la pasarela.
B21: Margen de contribución del mes | C21: =C19-C20 -> 107298.3 | D21: Lo que queda para cubrir los costos fijos.
B22: Utilidad mensual estimada | C22: =C21-C12 -> 29298.3 | D22: Margen de contribución menos los costos fijos.
B24: INDICADORES DEL MODELO
B25: Ingreso recurrente anual (ARR) | C25: =C17*12 -> 1186680 | D25: MRR proyectado a doce meses.
B26: Margen de contribución por cliente al mes | C26: =C6-C10-C6*C11 -> 777.03 | D26: Precio menos costo variable y comisión.
B27: Margen de contribución (porcentaje) | C27: =IFERROR(C26/C6,0) -> 0.86432703 | D27: Proporción del precio que sobrevive a los costos variables.
B28: Valor del cliente en toda la relación (LTV) | C28: =C26*C14+C7 -> 16486.54 | D28: Margen mensual por la permanencia, más la implementación.
B29: Relación LTV / CAC | C29: =IFERROR(C28/C13,0) -> 9.1591889 | D29: Por debajo de 3.0 el modelo no se sostiene: revisa precio, retención o canal.
B30: Meses para recuperar el CAC | C30: =IFERROR(C13/C26,0) -> 2.3165129 | D30: Más de 12 meses obliga a replantear el canal de venta.
B31: Punto de equilibrio (clientes activos necesarios) | C31: =IFERROR(ROUNDUP(C12/C26,0),0) -> 101 | D31: Clientes con los que el margen cubre exactamente los costos fijos.
B32: Diagnóstico de la relación LTV/CAC | C32: =IF(C29>=3,"Saludable: el modelo puede escalar.",IF(C29>=1,"Frágil: apenas recuperas lo invertido.","Inviable: cada cliente cuesta más de lo que deja.")) -> Saludable: el modelo puede escalar. | D32: Se recalcula al cambiar cualquier supuesto.
B34: Fuente de los supuestos: cifras propuestas por el equipo docente como ejemplo del caso TallerPro. Sustitúyelas por las de tu proyecto y anota de dónde salió cada una.

Sheet Checklist
B2: Prueba de coherencia del modelo
B3: Elige Sí, Parcial o No en cada criterio (celdas amarillas). El semáforo del final indica si la propuesta está lista para presentarse.
B5: # | C5: Criterio | D5: Respuesta | E5: Puntos | F5: Qué revisar si la respuesta no es «Sí»
B6: 1 | C6: Cada segmento de clientes tiene al menos un canal que lo alcanza. | D6: si | E6: =IF(D6="Sí",1,IF(D6="Parcial",0.5,0)) -> 0 | F6: Revisa el bloque 3: un segmento sin canal es un cliente al que nunca llegarás.
B7: 2 | C7: Cada segmento tiene una propuesta de valor escrita en sus términos, no en los tuyos. | E7: =IF(D7="Sí",1,IF(D7="Parcial",0.5,0)) -> 0 | F7: Reescribe el bloque 2 con las palabras que usó el cliente en las entrevistas.
B8: 3 | C8: Cada propuesta de valor tiene asociada al menos una fuente de ingresos. | E8: =IF(D8="Sí",1,IF(D8="Parcial",0.5,0)) -> 0 | F8: Si nadie paga por ese valor, es una función, no un modelo de negocio.
B9: 4 | C9: Cada actividad clave se sostiene con algún recurso clave o algún socio declarado. | E9: =IF(D9="Sí",1,IF(D9="Parcial",0.5,0)) -> 0 | F9: Cruza los bloques 6, 7 y 8: una actividad sin quien la ejecute no ocurrirá.
B10: 5 | C10: Cada costo relevante se origina en un recurso, una actividad o un socio de tu lienzo. | E10: =IF(D10="Sí",1,IF(D10="Parcial",0.5,0)) -> 0 | F10: Si aparece un costo sin origen, falta declarar algo en los bloques 6, 7 u 8.
B11: 6 | C11: El precio se justifica con el valor entregado, no con el costo de desarrollo. | D11: si | E11: =IF(D11="Sí",1,IF(D11="Parcial",0.5,0)) -> 0 | F11: Vuelve al bloque 5 y compáralo con lo que el cliente gasta hoy en el problema.
B12: 7 | C12: El tipo de relación con el cliente es compatible con el precio y con el costo de atenderlo. | D12: si | E12: =IF(D12="Sí",1,IF(D12="Parcial",0.5,0)) -> 0 | F12: Un acompañamiento personalizado con precio bajo destruye el margen.
B13: 8 | C13: Sabes cuál es el supuesto más riesgoso del modelo y cómo piensas ponerlo a prueba. | E13: =IF(D13="Sí",1,IF(D13="Parcial",0.5,0)) -> 0 | F13: Nómbralo y define el experimento y la fecha en que lo harás.
B14: 9 | C14: Hay al menos una evidencia externa: entrevista, prueba, carta de intención o dato de mercado. | D14: si | E14: =IF(D14="Sí",1,IF(D14="Parcial",0.5,0)) -> 0 | F14: Sin evidencia, todo el lienzo es opinión del equipo.
B15: 10 | C15: Puedes explicar el modelo completo en tres minutos sin abrir el sistema. | D15: si | E15: =IF(D15="Sí",1,IF(D15="Parcial",0.5,0)) -> 0 | F15: Si necesitas la demostración para explicarlo, el modelo aún no está claro.
C17: Puntaje obtenido (máximo 10) | E17: =SUM(E6:E15) -> 0
C18: Nivel de avance | E18: =E17/10 -> 0
C20: =IF(E18>=0.9,"VERDE — el modelo es coherente: pueden presentarlo.",IF(E18>=0.6,"AMARILLO — hay huecos: revisen los criterios que no quedaron en «Sí» antes de exponer.","ROJO — el modelo aún no se sostiene: regresen al cuestionario antes de preparar la presentación.")) -> ROJO — el modelo aún no se sostiene: regresen al cuestionario antes de preparar la presentación.
